<?xml version="1.0"?>
<robot name="physics">

    <link name="world">
    <visual>
      <origin rpy="0 1.57079632679 0" xyz="0 0 0"/>
      <geometry>
        <cylinder radius="0.05" length="0.1"/>
      </geometry>
      <origin xyz="0 0 0"/>
      <material name="red">
        <color rgba=".8 0 0 1"/>
      </material>
    </visual>
    <inertial>
      <mass value="0"/>
      <inertia ixx="1.0" ixy="0.0" ixz="0.0" iyy="1.0" iyz="0.0" izz="1.0"/>
    </inertial>
  </link>

  <link name="pole1">
    <visual>
      <origin rpy="0 0 0" xyz="0 0 0.5"/>
      <geometry>
        <cylinder  radius="0.04" length="1"/>	
      </geometry>
      <origin rpy="0 0 0" xyz="0 0 0"/>
      <material name="white">
        <color rgba="1 1 1 1"/>
      </material>
    </visual>
    <inertial>
    <origin xyz="0 0 1"/>
      <mass value="1"/>
      <inertia ixx="0" ixy="0.0" ixz="0.0" iyy="0.0" iyz="0.0" izz="0.0"/>
    </inertial>
     <collision>
      <geometry>
        <box size="0.05 0.05 1.0"/>	
      </geometry>
      <origin rpy="0 0 0" xyz="0 0 0.5"/>
    </collision>
  </link>

  <joint name="pole1" type="revolute">
    <axis xyz="1 0 0"/>
    <origin xyz="0.0 0.0 0"/>
    <parent link="world"/>
    <child link="pole1"/>
    <limit effort="1000.0" velocity="5"/>
  </joint>

  <link name="pole2">
    <visual>
      <origin rpy="0 0 0" xyz="0 0 0.5"/>
      <geometry>
        <cylinder  radius="0.04" length="1"/>	
      </geometry>
      <material name="white">
        <color rgba="1 1 1 1"/>
      </material>
    </visual>
    <visual>
      <origin rpy="0 0 0" xyz="0 0 0"/>
      <geometry>
        <sphere radius="0.1"/>
      </geometry>
      <material name="red">
        <color rgba=".8 0 0 1"/>
      </material>
    </visual>
    <inertial>
    <origin xyz="0 0 1"/>
      <mass value="1"/>
      <inertia ixx="0" ixy="0.0" ixz="0.0" iyy="0.0" iyz="0.0" izz="0.0"/>
    </inertial>
     <collision>
      <geometry>
        <box size="0.05 0.05 1.0"/>	
      </geometry>
      <origin rpy="0 0 0" xyz="0 0 0.5"/>
    </collision>
  </link>

  <joint name="pole2" type="revolute">
    <axis xyz="1 0 0"/>
    <origin xyz="0.0 0.0 1.0"/>
    <parent link="pole1"/>
    <child link="pole2"/>
    <limit effort="1000.0" velocity="5"/>
  </joint>

  <link name="pole_tip">
    <visual>
      <origin rpy="0 0 0" xyz="0 0 0"/>
      <geometry>
        <sphere radius="0.1"/>
      </geometry>
      <origin xyz="0 0 0"/>
      <material name="red">
        <color rgba=".8 0 0 1"/>
      </material>
    </visual>
  </link>

  <joint name="tip_joint" type="fixed">
    <origin xyz="0 0 1"/>
    <parent link="pole2"/>
    <child link="pole_tip"/>
  </joint>
  
</robot>
